Workbook

Sheet ReadMe
B1: IFC -> Bill of Quantities
B3: Source file | C3: Ifc2x3_Duplex_Architecture.ifc
B4: Schema | C4: IFC2X3
B5: Authoring tool | C5: Autodesk Revit Architecture 2011
B6: Units | C6: Metres / m2 / m3 (from IfcUnitAssignment)
B7: Storeys | C7: T/FDN (-1.25), Level 1 (+0.00), Level 2 (+3.10), Roof (+6.00)
B8: Elements measured | C8: 211 physical elements + 21 spaces
B10: Pipeline | C10: 1. Extract (extract.py): IFC -> unified.json. Per element: reported quantities, geometry-measured volume/area, type, storey, material layers, host/aggregate links.
C11: 2. Verify (extract.py + overlap.py): every solid re-meshed and measured; reported vs geometric volume compared at 1% tolerance; pairwise solid intersections to catch double counting.
C12: 3. Classify & measure (classify.py): rule table maps class + type (+ storey) to a BoQ item key; adopts a quantity per element with a stated source.
C13: 4. Present (build_boq.py): this workbook. BoQ lines are SUMIFS over the Register, so keys, parameters and the naming dictionary can be edited live.
B15: Sheets | C15: BoQ - priced-bill layout, rates column blank. Register - one row per element, with the reasoning behind each number. Openings - door/window schedule with host walls.
C16: Materials - layer-by-layer take-off + editable naming dictionary. Rooms - space schedule and NIA. QA - findings and decisions. Params - editable rule parameters.
B18: Colour legend | C18: Yellow fill + blue text = input you can edit (rates, parameters, NIA flags, material names). Black = formula or extracted value.
B19: Register flags | C19: Resolved (green) = discrepancy found and explained. Minor (orange) = small known deviation, handled by a different measure. Check (red) = needs a human.

Sheet BoQ
A1: Bill of Quantities - Ifc2x3_Duplex_Architecture.ifc
A2: Elemental grouping modelled on NRM1. Quantities are live formulas over the Register. Enter rates in the yellow column.
A4: Ref | B4: Description | C4: Unit | D4: Quantity | E4: Rate | F4: Amount | G4: Measurement basis / source
A5: 1 | B5: SUBSTRUCTURE
A6: 1.01 | B6: In-situ concrete strip footings, 900 x 300 mm | C6: m3 | D6: =SUMIFS(Register!$J:$J,Register!$F:$F,"1.01") -> 16.52805 | F6: =D6*E6 -> 0 | G6: Reported (Revit) volume, geometry-verified; material assumed concrete (none in IFC)
A7: 1.02 | B7: Formwork to vertical sides of strip footings (derived: 2 x length x depth) | C7: m2 | D7: =2*SUMIFS(Register!$H:$H,Register!$F:$F,"1.01")*Params!$B$6 -> 37.0188 | F7: =D7*E7 -> 0 | G7: Derived from reported footing length
A8: 1.03 | B8: In-situ concrete foundation walls, 417 mm thick | C8: m3 | D8: =SUMIFS(Register!$J:$J,Register!$F:$F,"1.03") -> 26.861055 | F8: =D8*E8 -> 0 | G8: Reported (Revit) volume, geometry-verified
A9: 1.04 | B9: In-situ concrete foundation walls, 435 mm thick | C9: m3 | D9: =SUMIFS(Register!$J:$J,Register!$F:$F,"1.04") -> 5.4302551 | F9: =D9*E9 -> 0 | G9: Reported (Revit) volume, geometry-verified
A10: 1.05 | B10: Formwork to both faces of foundation walls (derived: 2 x net area) | C10: m2 | D10: =2*(SUMIFS(Register!$I:$I,Register!$F:$F,"1.03")+SUMIFS(Register!$I:$I,Register!$F:$F,"1.04")) -> 153.79669 | F10: =D10*E10 -> 0 | G10: Derived from adopted wall area
A11: 1.06 | B11: In-situ concrete ground-bearing slab, 127 mm thick | C11: m3 | D11: =SUMIFS(Register!$J:$J,Register!$F:$F,"1.06") -> 16.470167 | F11: =D11*E11 -> 0 | G11: Reported (Revit) volume, geometry-verified
A12: 1.07 | B12: Ground-bearing slab 127 mm - surface area (for DPM, mesh, power-floating) | C12: m2 | D12: =SUMIFS(Register!$I:$I,Register!$F:$F,"1.06") -> 129.68636 | F12: =D12*E12 -> 0 | G12: Reported area
A13: 1.08 | B13: Edge formwork to ground slab, 127 mm high (derived: perimeter x thickness) | C13: m2 | D13: =SUMIFS(Register!$K:$K,Register!$F:$F,"1.06")*Params!$B$7 -> 8.775192 | F13: =D13*E13 -> 0 | G13: Derived from reported perimeter
B14: Subtotal Substructure | F14: =SUM(F6:F13) -> 0
A16: 2.1 | B16: FRAME
A17: 2.1.1 | B17: Structural steel beam W310x60, grade 345 MPa | C17: t | D17: =SUMIFS(Register!$N:$N,Register!$F:$F,"2.1.1")/1000 -> 0.90276 | F17: =D17*E17 -> 0 | G17: Reported length x nominal 60 kg/m (volume x density in Register as check)
A18: 2.1.2 | B18: Structural steel beam W410x60, grade 345 MPa | C18: t | D18: =SUMIFS(Register!$N:$N,Register!$F:$F,"2.1.2")/1000 -> 1.72838 | F18: =D18*E18 -> 0 | G18: Reported length x nominal 60 kg/m
B19: Subtotal Frame | F19: =SUM(F17:F18) -> 0
A21: 2.2 | B21: UPPER FLOORS
A22: 2.2.1 | B22: Timber joist floor: 286 mm dimensional lumber joists, 19 mm plywood subfloor (305 mm overall) | C22: m2 | D22: =SUMIFS(Register!$I:$I,Register!$F:$F,"2.2.1") -> 118.56277 | F22: =D22*E22 -> 0 | G22: Reported area, V/t-consistent
B23: Subtotal Upper Floors | F23: =SUM(F22:F22) -> 0
A25: 2.3 | B25: ROOF
A26: 2.3.1 | B26: Flat live (green) roof: 64 mm growing medium, root barrier, EPDM membrane, 76 mm rigid insulation, 19 mm plywood, 286 mm timber joists (457 mm) | C26: m2 | D26: =SUMIFS(Register!$I:$I,Register!$F:$F,"2.3.1") -> 132.92604 | F26: =D26*E26 -> 0 | G26: Reported area on IfcRoof; geometry from child slab
A27: 2.3.2 | B27: Roof light, 1180 x 1170 mm | C27: nr | D27: =SUMIFS(Register!$G:$G,Register!$F:$F,"2.3.2") -> 2 | F27: =D27*E27 -> 0 | G27: Count
B28: Subtotal Roof | F28: =SUM(F26:F27) -> 0
A30: 2.4 | B30: STAIRS AND RAMPS
A31: 2.4.1 | B31: Straight-flight stair, 16 risers @ 193.75 mm, 250 mm going, 1000 mm wide, Level 1 to Level 2 (material not defined in model) | C31: nr | D31: =SUMIFS(Register!$G:$G,Register!$F:$F,"2.4.1") -> 2 | F31: =D31*E31 -> 0 | G31: Count; geometry and riser data from Pset_StairFlightCommon
A32: 2.4.2 | B32: Handrail, 900 mm high | C32: m | D32: =SUMIFS(Register!$H:$H,Register!$F:$F,"2.4.2") -> 9.4886857 | F32: =D32*E32 -> 0 | G32: Reported length
A33: 2.4.3 | B33: Guard rail, 1100 mm high | C33: m | D33: =SUMIFS(Register!$H:$H,Register!$F:$F,"2.4.3") -> 16.668686 | F33: =D33*E33 -> 0 | G33: Reported length
B34: Subtotal Stairs And Ramps | F34: =SUM(F31:F33) -> 0
A36: 2.5 | B36: EXTERNAL WALLS
A37: 2.5.1 | B37: Cavity wall: 92 mm brick, 25 mm cavity, 50 mm rigid insulation, 193 mm concrete block, 41 mm metal stud, 16 mm plasterboard (417 mm) | C37: m2 | D37: =SUMIFS(Register!$I:$I,Register!$F:$F,"2.5.1")+SUMIFS(Openings!$G:$G,Openings!$J:$J,"2.5.1",Openings!$G:$G,"<="&Params!$B$5) -> 235.77923 | F37: =D37*E37 -> 0 | G37: Net area = volume / layer-set thickness (all openings deducted), + add-back of openings <= threshold (Params)
A38: 2.5.2 | B38: Ditto, parapet above roof level | C38: m2 | D38: =SUMIFS(Register!$I:$I,Register!$F:$F,"2.5.2")+SUMIFS(Openings!$G:$G,Openings!$J:$J,"2.5.2",Openings!$G:$G,"<="&Params!$B$5) -> 31.382988 | F38: =D38*E38 -> 0 | G38: Net area = volume / layer-set thickness (all openings deducted), + add-back of openings <= threshold (Params)
B39: Subtotal External Walls | F39: =SUM(F37:F38) -> 0
A41: 2.6 | B41: WINDOWS AND EXTERNAL DOORS
A42: 2.6.1 | B42: Fixed window, 4835 x 2420 mm | C42: nr | D42: =SUMIFS(Register!$G:$G,Register!$F:$F,"2.6.1") -> 2 | F42: =D42*E42 -> 0 | G42: Count
A43: 2.6.2 | B43: Fixed window, 2800 x 2410 mm | C43: nr | D43: =SUMIFS(Register!$G:$G,Register!$F:$F,"2.6.2") -> 4 | F43: =D43*E43 -> 0 | G43: Count
A44: 2.6.3 | B44: Fixed window, 750 x 2200 mm | C44: nr | D44: =SUMIFS(Register!$G:$G,Register!$F:$F,"2.6.3") -> 4 | F44: =D44*E44 -> 0 | G44: Count
A45: 2.6.4 | B45: Fixed window, 819 x 759 mm | C45: nr | D45: =SUMIFS(Register!$G:$G,Register!$F:$F,"2.6.4") -> 8 | F45: =D45*E45 -> 0 | G45: Count
A46: 2.6.5 | B46: Casement window, 819 x 759 mm | C46: nr | D46: =SUMIFS(Register!$G:$G,Register!$F:$F,"2.6.5") -> 4 | F46: =D46*E46 -> 0 | G46: Count
A47: 2.6.6 | B47: External door, single flush, 1250 x 2010 mm | C47: nr | D47: =SUMIFS(Register!$G:$G,Register!$F:$F,"2.6.6") -> 2 | F47: =D47*E47 -> 0 | G47: Count
...

Sheet Register
A1: GUID | B1: IFC class | C1: Family | D1: Type | E1: Storey | F1: BoQ key | G1: Count | H1: Length (m) | I1: Area adopted (m2) | J1: Volume adopted (m3) | K1: Perimeter (m) | L1: Layer-set thickness (mm) | M1: Nominal mass (kg/m) | N1: Mass (kg) | O1: Mass check: vol x density (kg) | P1: Reported area (m2) | Q1: Reported volume (m3) | R1: Geometric volume (m3) | S1: Geom vs reported | T1: Quantity source / reasoning | U1: Flag | V1: Revit Id
A2: 0kF45Qs8L9PAM9kmb1lT5d | B2: IfcFooting | C2: Wall Foundation | D2: Bearing Footing - 900 x 300 | E2: T/FDN | F2: 1.01 | G2: 1 | H2: 17.383 | J2: 4.93641 | Q2: 4.93641 | R2: 4.93641 | S2: =(R2-Q2)/Q2 -> 0 | T2: Reported (Revit), geometry-verified; no material assigned in IFC - concrete assumed from type name | V2: 186596
A3: 0kF45Qs8L9PAM9kmb1lT5l | B3: IfcFooting | C3: Wall Foundation | D3: Bearing Footing - 900 x 300 | E3: T/FDN | F3: 1.01 | G3: 1 | H3: 8.383 | J3: 2.26341 | Q3: 2.26341 | R3: 2.26341 | S3: =(R3-Q3)/Q3 -> 0 | T3: Reported (Revit), geometry-verified; no material assigned in IFC - concrete assumed from type name | V3: 186604
A4: 0kF45Qs8L9PAM9kmb1lT5t | B4: IfcFooting | C4: Wall Foundation | D4: Bearing Footing - 900 x 300 | E4: T/FDN | F4: 1.01 | G4: 1 | H4: 16.966 | J4: 4.69341 | Q4: 4.69341 | R4: 4.69341 | S4: =(R4-Q4)/Q4 -> 0 | T4: Reported (Revit), geometry-verified; no material assigned in IFC - concrete assumed from type name | V4: 186612
A5: 0kF45Qs8L9PAM9kmb1lT5$ | B5: IfcFooting | C5: Wall Foundation | D5: Bearing Footing - 900 x 300 | E5: T/FDN | F5: 1.01 | G5: 1 | H5: 8.8 | J5: 2.02041 | Q5: 2.02041 | R5: 2.02041 | S5: =(R5-Q5)/Q5 -> 0 | T5: Reported (Revit), geometry-verified; no material assigned in IFC - concrete assumed from type name | V5: 186620
A6: 0kF45Qs8L9PAM9kmb1lT2B | B6: IfcFooting | C6: Wall Foundation | D6: Bearing Footing - 900 x 300 | E6: T/FDN | F6: 1.01 | G6: 1 | H6: 4.2005 | J6: 1.131705 | Q6: 1.131705 | R6: 1.131705 | S6: =(R6-Q6)/Q6 -> 0 | T6: Reported (Revit), geometry-verified; no material assigned in IFC - concrete assumed from type name | V6: 186632
A7: 0kF45Qs8L9PAM9kmb1lT2N | B7: IfcFooting | C7: Wall Foundation | D7: Bearing Footing - 900 x 300 | E7: T/FDN | F7: 1.01 | G7: 1 | H7: 1.765 | J7: 0.594 | Q7: 0.594 | R7: 0.594 | S7: =(R7-Q7)/Q7 -> 0 | T7: Reported (Revit), geometry-verified; no material assigned in IFC - concrete assumed from type name | V7: 186644
A8: 0kF45Qs8L9PAM9kmb1lT2Z | B8: IfcFooting | C8: Wall Foundation | D8: Bearing Footing - 900 x 300 | E8: T/FDN | F8: 1.01 | G8: 1 | H8: 4.2005 | J8: 0.888705 | Q8: 0.888705 | R8: 0.888705 | S8: =(R8-Q8)/Q8 -> 0 | T8: Reported (Revit), geometry-verified; no material assigned in IFC - concrete assumed from type name | V8: 186656
A9: 2O2Fr$t4X7Zf8NOew3FK80 | B9: IfcWallStandardCase | C9: Basic Wall | D9: Foundation - Concrete (417mm) | E9: T/FDN | F9: 1.03 | G9: 1 | H9: 8.383 | I9: =IF(L9>0,J9/(L9/1000),"") -> 11 | J9: 4.587 | L9: 417 | P9: 11 | Q9: 4.587 | R9: 4.587 | S9: =(R9-Q9)/Q9 -> 0 | T9: Reported (Revit), geometry-verified | V9: 140479
A10: 2O2Fr$t4X7Zf8NOew3FK9N | B10: IfcWallStandardCase | C10: Basic Wall | D10: Foundation - Concrete (417mm) | E10: T/FDN | F10: 1.03 | G10: 1 | H10: 17.383 | I10: =IF(L10>0,J10/(L10/1000),"") -> 21.72875 | J10: 9.0608888 | L10: 417 | P10: 21.72875 | Q10: 9.0608888 | R10: 9.0608888 | S10: =(R10-Q10)/Q10 -> 0 | T10: Reported (Revit), geometry-verified | V10: 140520
A11: 2O2Fr$t4X7Zf8NOew3FKEr | B11: IfcWallStandardCase | C11: Basic Wall | D11: Foundation - Concrete (417mm) | E11: T/FDN | F11: 1.03 | G11: 1 | H11: 8.383 | I11: =IF(L11>0,J11/(L11/1000),"") -> 10.47875 | J11: 4.3696387 | L11: 417 | P11: 10.47875 | Q11: 4.3696387 | R11: 4.3696388 | S11: =(R11-Q11)/Q11 -> 0 | T11: Reported (Revit), geometry-verified | V11: 140554
A12: 2O2Fr$t4X7Zf8NOew3FKE5 | B12: IfcWallStandardCase | C12: Basic Wall | D12: Foundation - Concrete (417mm) | E12: T/FDN | F12: 1.03 | G12: 1 | H12: 17.383 | I12: =IF(L12>0,J12/(L12/1000),"") -> 21.2075 | J12: 8.8435275 | L12: 417 | P12: 21.2075 | Q12: 8.8435275 | R12: 8.8435275 | S12: =(R12-Q12)/Q12 -> 0 | T12: Reported (Revit), geometry-verified | V12: 140602
A13: 2O2Fr$t4X7Zf8NOew3FK3E | B13: IfcWallStandardCase | C13: Basic Wall | D13: Foundation - Concrete (435mm) | E13: T/FDN | F13: 1.04 | G13: 1 | H13: 4.1915 | I13: =IF(L13>0,J13/(L13/1000),"") -> 5.250625 | J13: 2.2840219 | L13: 435 | P13: 5.250625 | Q13: 2.2840219 | R13: 2.2840219 | S13: =(R13-Q13)/Q13 -> 4.2775259e-15 | T13: Reported (Revit), geometry-verified | V13: 140913
A14: 2O2Fr$t4X7Zf8NOew3FK04 | B14: IfcWallStandardCase | C14: Basic Wall | D14: Foundation - Concrete (435mm) | E14: T/FDN | F14: 1.04 | G14: 1 | H14: 4.1915 | I14: =IF(L14>0,J14/(L14/1000),"") -> 5.250625 | J14: 2.2840219 | L14: 435 | P14: 5.250625 | Q14: 2.2840219 | R14: 2.2840219 | S14: =(R14-Q14)/Q14 -> 3.8886599e-15 | T14: Reported (Revit), geometry-verified | V14: 140987
A15: 2O2Fr$t4X7Zf8NOew3FK1b | B15: IfcWallStandardCase | C15: Basic Wall | D15: Foundation - Concrete (435mm) | E15: T/FDN | F15: 1.04 | G15: 1 | H15: 2.2 | I15: =IF(L15>0,J15/(L15/1000),"") -> 1.982095 | J15: 0.86221133 | L15: 435 | P15: 1.982095 | Q15: 0.86221133 | R15: 0.86221133 | S15: =(R15-Q15)/Q15 -> 0 | T15: Reported (Revit), geometry-verified | V15: 141018
A16: 2O2Fr$t4X7Zf8NOew3FK4F | B16: IfcSlab | C16: Floor | D16: 127mm Slab on Grade | E16: Level 1 | F16: 1.06 | G16: 1 | I16: 64.779928 | J16: 8.2270509 | K16: 34.548 | L16: 127 | P16: 64.779928 | Q16: 8.2270509 | R16: 8.2270509 | S16: =(R16-Q16)/Q16 -> 0 | T16: Reported (Revit), geometry-verified | V16: 141232
A17: 2O2Fr$t4X7Zf8NOew3FKcz | B17: IfcSlab | C17: Floor | D17: 127mm Slab on Grade | E17: Level 1 | F17: 1.06 | G17: 1 | I17: 64.906428 | J17: 8.2431164 | K17: 34.548 | L17: 127 | P17: 64.906428 | Q17: 8.2431164 | R17: 8.2431164 | S17: =(R17-Q17)/Q17 -> 0 | T17: Reported (Revit), geometry-verified | V17: 143106
A18: 2OrWItJ6zAwBNp0OUxK_l8 | B18: IfcBeam | C18: M_W-Wide Flange | D18: W310X60 | E18: Level 1 | F18: 2.1.1 | G18: 1 | H18: 7.523 | J18: 0.054877545 | M18: 60 | N18: =H18*M18 -> 451.38 | O18: =J18*Params!$B$4 -> 430.78873 | Q18: 0.054877545 | R18: 0.057477618 | S18: =(R18-Q18)/Q18 -> 0.047379546 | T18: Reported (Revit); geometry +4.7% - steel measured by nominal mass instead | U18: Minor | V18: 207325
A19: 2OrWItJ6zAwBNp0OUxK$Dv | B19: IfcBeam | C19: M_W-Wide Flange | D19: W310X60 | E19: Level 1 | F19: 2.1.1 | G19: 1 | H19: 7.523 | J19: 0.054877545 | M19: 60 | N19: =H19*M19 -> 451.38 | O19: =J19*Params!$B$4 -> 430.78873 | Q19: 0.054877545 | R19: 0.057477618 | S19: =(R19-Q19)/Q19 -> 0.047379546 | T19: Reported (Revit); geometry +4.7% - steel measured by nominal mass instead | U19: Minor | V19: 209260
A20: 2OrWItJ6zAwBNp0OUxK$8W | B20: IfcBeam | C20: M_W-Wide Flange | D20: W410X60 | E20: Level 1 | F20: 2.1.2 | G20: 1 | H20: 6.1818871 | J20: 0.046324466 | M20: 60 | N20: =H20*M20 -> 370.91323 | O20: =J20*Params!$B$4 -> 363.64706 | Q20: 0.046324466 | R20: 0.047942461 | S20: =(R20-Q20)/Q20 -> 0.034927457 | T20: Reported (Revit); geometry +3.5% - steel measured by nominal mass instead | U20: Minor | V20: 208949
A21: 2OrWItJ6zAwBNp0OUxK$Du | B21: IfcBeam | C21: M_W-Wide Flange | D21: W410X60 | E21: Level 1 | F21: 2.1.2 | G21: 1 | H21: 6.1818871 | J21: 0.046324466 | M21: 60 | N21: =H21*M21 -> 370.91323 | O21: =J21*Params!$B$4 -> 363.64706 | Q21: 0.046324466 | R21: 0.047942461 | S21: =(R21-Q21)/Q21 -> 0.034927457 | T21: Reported (Revit); geometry +3.5% - steel measured by nominal mass instead | U21: Minor | V21: 209261
A22: 2OrWItJ6zAwBNp0OUxK$Bq | B22: IfcBeam | C22: M_W-Wide Flange | D22: W410X60 | E22: Level 2 | F22: 2.1.2 | G22: 1 | H22: 4.1212799 | J22: 0.030883141 | M22: 60 | N22: =H22*M22 -> 247.2768 | O22: =J22*Params!$B$4 -> 242.43266 | Q22: 0.030883141 | R22: 0.03196181 | S22: =(R22-Q22)/Q22 -> 0.034927457 | T22: Reported (Revit); geometry +3.5% - steel measured by nominal mass instead | U22: Minor | V22: 209121
A23: 2OrWItJ6zAwBNp0OUxK$CR | B23: IfcBeam | C23: M_W-Wide Flange | D23: W410X60 | E23: Level 2 | F23: 2.1.2 | G23: 1 | H23: 4.1 | J23: 0.030723678 | M23: 60 | N23: =H23*M23 -> 246 | O23: =J23*Params!$B$4 -> 241.18087 | Q23: 0.030723678 | R23: 0.031796778 | S23: =(R23-Q23)/Q23 -> 0.034927457 | T23: Reported (Revit); geometry +3.5% - steel measured by nominal mass instead | U23: Minor | V23: 209166
A24: 2OrWItJ6zAwBNp0OUxK$Dx | B24: IfcBeam | C24: M_W-Wide Flange | D24: W410X60 | E24: Level 2 | F24: 2.1.2 | G24: 1 | H24: 4.1212799 | J24: 0.030883141 | M24: 60 | N24: =H24*M24 -> 247.2768 | O24: =J24*Params!$B$4 -> 242.43266 | Q24: 0.030883141 | R24: 0.03196181 | S24: =(R24-Q24)/Q24 -> 0.034927457 | T24: Reported (Revit); geometry +3.5% - steel measured by nominal mass instead | U24: Minor | V24: 209262
A25: 2OrWItJ6zAwBNp0OUxK$Dw | B25: IfcBeam | C25: M_W-Wide Flange | D25: W410X60 | E25: Level 2 | F25: 2.1.2 | G25: 1 | H25: 4.1 | J25: 0.030723678 | M25: 60 | N25: =H25*M25 -> 246 | O25: =J25*Params!$B$4 -> 241.18087 | Q25: 0.030723678 | R25: 0.031796778 | S25: =(R25-Q25)/Q25 -> 0.034927457 | T25: Reported (Revit); geometry +3.5% - steel measured by nominal mass instead | U25: Minor | V25: 209263
A26: 1hOSvn6df7F8_7GcBWlRqU | B26: IfcSlab | C26: Floor | D26: Residential - Wood Joist with Subflooring | E26: Level 2 | F26: 2.2.1 | G26: 1 | I26: 59.229018 | J26: 18.06485 | K26: 43.4568 | L26: 305 | P26: 59.229018 | Q26: 18.06485 | R26: 18.06485 | S26: =(R26-Q26)/Q26 -> 0 | T26: Reported (Revit), geometry-verified | V26: 144800
A27: 1hOSvn6df7F8_7GcBWlRrM | B27: IfcSlab | C27: Floor | D27: Residential - Wood Joist with Subflooring | E27: Level 2 | F27: 2.2.1 | G27: 1 | I27: 59.333748 | J27: 18.096793 | K27: 43.3968 | L27: 305 | P27: 59.333748 | Q27: 18.096793 | R27: 18.096793 | S27: =(R27-Q27)/Q27 -> 0 | T27: Reported (Revit), geometry-verified | V27: 144872
A28: 0jf0rYHfX3RAB3bSIRjmxl | B28: IfcRoof | C28: Basic Roof | D28: Live Roof over Wood Joist Flat Roof | E28: Roof | F28: 2.3.1 | G28: 1 | I28: 132.92604 | J28: 60.747198 | L28: 457 | P28: 132.92604 | Q28: 60.747198 | R28: 60.804399 | S28: =(R28-Q28)/Q28 -> 0.00094161486 | T28: Reported (Revit), geometry-verified; mesh had inconsistent face winding (repaired before measuring) | V28: 184483
A29: 1Eo2$BaHX42AEkDvQQDocD | B29: IfcWindow | C29: M_Skylight | D29: 1180 x 1170mm | E29: Roof | F29: 2.3.2 | G29: 1 | R29: 0.028600232 | T29: Count | V29: 185337
A30: 1Eo2$BaHX42AEkDvQQDoy2 | B30: IfcWindow | C30: M_Skylight | D30: 1180 x 1170mm | E30: Roof | F30: 2.3.2 | G30: 1 | R30: 0.028600232 | T30: Count | V30: 185718
A31: 0wkEuT1wr1kOyafLY4v_O1 | B31: IfcStair | C31: Stair | D31: Residential - 200mm Max Riser 250mm Tread | E31: Level 1 | F31: 2.4.1 | G31: 1 | J31: 0.41343325 | R31: 0.41343325 | T31: Geometry (sum of child solids: flight, stringers, rails) - for information; no reported quantities | V31: 151086
A32: 21ldoMpbP4VfsJ0XGY_34d | B32: IfcStair | C32: Stair | D32: Residential - 200mm Max Riser 250mm Tread | E32: Level 1 | F32: 2.4.1 | G32: 1 | J32: 0.41001085 | R32: 0.41001085 | T32: Geometry (sum of child solids: flight, stringers, rails) - for information; no reported quantities | V32: 198878
A33: 0wkEuT1wr1kOyafLY4v_PL | B33: IfcRailing | C33: Railing | D33: 900mm Handrail Only | E33: Level 1 | F33: 2.4.2 | G33: 1 | H33: 4.7443428 | R33: 0.0058940766 | T33: Reported length (Revit) | V33: 151162
A34: 21ldoMpbP4VfsJ0XGY_34P | B34: IfcRailing | C34: Railing | D34: 900mm Handrail Only | E34: Level 1 | F34: 2.4.2 | G34: 1 | H34: 4.7443428 | R34: 0.0058940438 | T34: Reported length (Revit) | V34: 198880
A35: 0wkEuT1wr1kOyafLY4v_PH | B35: IfcRailing | C35: Railing | D35: 1100mm Guard Rail | E35: Level 1 | F35: 2.4.3 | G35: 1 | H35: 8.3343428 | R35: 0.013851298 | T35: Reported length (Revit) | V35: 151166
A36: 21ldoMpbP4VfsJ0XGY_335 | B36: IfcRailing | C36: Railing | D36: 1100mm Guard Rail | E36: Level 1 | F36: 2.4.3 | G36: 1 | H36: 8.3343428 | R36: 0.010428926 | T36: Reported length (Revit) | V36: 198972
A37: 2O2Fr$t4X7Zf8NOew3FNtn | B37: IfcWallStandardCase | C37: Basic Wall | D37: Exterior - Brick on Block | E37: Level 1 | F37: 2.5.1 | G37: 1 | H37: 8.383 | I37: =IF(L37>0,J37/(L37/1000),"") -> 13.61184 | J37: 5.6761373 | L37: 417 | P37: 13.61184 | Q37: 5.6761373 | R37: 5.6761373 | S37: =(R37-Q37)/Q37 -> 0 | T37: Reported (Revit), geometry-verified | V37: 138062
A38: 2O2Fr$t4X7Zf8NOew3FNqI | B38: IfcWallStandardCase | C38: Basic Wall | D38: Exterior - Brick on Block | E38: Level 1 | F38: 2.5.1 | G38: 1 | H38: 17.383 | I38: =IF(L38>0,J38/(L38/1000),"") -> 49.7248 | J38: 20.735242 | L38: 417 | P38: 49.7248 | Q38: 20.735242 | R38: 20.735242 | S38: =(R38-Q38)/Q38 -> 0 | T38: Reported (Revit), geometry-verified | V38: 138157
A39: 2O2Fr$t4X7Zf8NOew3FNr2 | B39: IfcWallStandardCase | C39: Basic Wall | D39: Exterior - Brick on Block | E39: Level 1 | F39: 2.5.1 | G39: 1 | H39: 8.383 | I39: =IF(L39>0,J39/(L39/1000),"") -> 12.31914 | J39: 5.1370814 | L39: 417 | P39: 12.31914 | Q39: 5.1370814 | R39: 5.1370814 | S39: =(R39-Q39)/Q39 -> 0 | T39: Reported (Revit), geometry-verified | V39: 138237
A40: 2O2Fr$t4X7Zf8NOew3FNhv | B40: IfcWallStandardCase | C40: Basic Wall | D40: Exterior - Brick on Block | E40: Level 1 | F40: 2.5.1 | G40: 1 | H40: 17.383 | I40: =IF(L40>0,J40/(L40/1000),"") -> 48.4321 | J40: 20.196186 | L40: 417 | P40: 48.4321 | Q40: 20.196186 | R40: 20.196186 | S40: =(R40-Q40)/Q40 -> 0 | T40: Reported (Revit), geometry-verified | V40: 138310
...

Sheet Openings
A1: GUID | B1: IFC class | C1: Type | D1: Storey | E1: Width (m) | F1: Height (m) | G1: Area W x H (m2) | H1: External | I1: Host element type | J1: Host BoQ key | K1: Own BoQ key
A2: 1Eo2$BaHX42AEkDvQQDocD | B2: IfcWindow | C2: 1180 x 1170mm | D2: Roof | E2: 1.1725377 | F2: 0.6348 | G2: =E2*F2 -> 0.74432692 | H2: No | I2: Live Roof over Wood Joist Flat Roof | J2: 2.3.1 | K2: 2.3.2
A3: 1Eo2$BaHX42AEkDvQQDoy2 | B3: IfcWindow | C3: 1180 x 1170mm | D3: Roof | E3: 1.1725377 | F3: 0.6348 | G3: =E3*F3 -> 0.74432692 | H3: No | I3: Live Roof over Wood Joist Flat Roof | J3: 2.3.1 | K3: 2.3.2
A4: 1hOSvn6df7F8_7GcBWlR72 | B4: IfcWindow | C4: 4835mm x 2420mm | D4: Level 1 | E4: 4.835 | F4: 2.42 | G4: =E4*F4 -> 11.7007 | H4: Yes | I4: Exterior - Brick on Block | J4: 2.5.1 | K4: 2.6.1
A5: 1hOSvn6df7F8_7GcBWlRBU | B5: IfcWindow | C5: 4835mm x 2420mm | D5: Level 1 | E5: 4.835 | F5: 2.42 | G5: =E5*F5 -> 11.7007 | H5: Yes | I5: Exterior - Brick on Block | J5: 2.5.1 | K5: 2.6.1
A6: 1hOSvn6df7F8_7GcBWlSXO | B6: IfcWindow | C6: 2800mm x 2410mm | D6: Level 2 | E6: 2.8 | F6: 2.41 | G6: =E6*F6 -> 6.748 | H6: Yes | I6: Exterior - Brick on Block | J6: 2.5.1 | K6: 2.6.2
A7: 1hOSvn6df7F8_7GcBWlS_W | B7: IfcWindow | C7: 2800mm x 2410mm | D7: Level 2 | E7: 2.8 | F7: 2.41 | G7: =E7*F7 -> 6.748 | H7: Yes | I7: Exterior - Brick on Block | J7: 2.5.1 | K7: 2.6.2
A8: 1l0GAJtRTFv8$zmKJOH4$e | B8: IfcWindow | C8: 2800mm x 2410mm | D8: Level 2 | E8: 2.8 | F8: 2.41 | G8: =E8*F8 -> 6.748 | H8: Yes | I8: Exterior - Brick on Block | J8: 2.5.1 | K8: 2.6.2
A9: 1l0GAJtRTFv8$zmKJOH4pU | B9: IfcWindow | C9: 2800mm x 2410mm | D9: Level 2 | E9: 2.8 | F9: 2.41 | G9: =E9*F9 -> 6.748 | H9: Yes | I9: Exterior - Brick on Block | J9: 2.5.1 | K9: 2.6.2
A10: 1hOSvn6df7F8_7GcBWlRLx | B10: IfcWindow | C10: 750mm x 2200mm | D10: Level 1 | E10: 0.75 | F10: 2.2 | G10: =E10*F10 -> 1.65 | H10: Yes | I10: Exterior - Brick on Block | J10: 2.5.1 | K10: 2.6.3
A11: 1hOSvn6df7F8_7GcBWlRRL | B11: IfcWindow | C11: 750mm x 2200mm | D11: Level 1 | E11: 0.75 | F11: 2.2 | G11: =E11*F11 -> 1.65 | H11: Yes | I11: Exterior - Brick on Block | J11: 2.5.1 | K11: 2.6.3
A12: 1l0GAJtRTFv8$zmKJOH4aS | B12: IfcWindow | C12: 750mm x 2200mm | D12: Level 2 | E12: 0.75 | F12: 2.2 | G12: =E12*F12 -> 1.65 | H12: Yes | I12: Exterior - Brick on Block | J12: 2.5.1 | K12: 2.6.3
A13: 1l0GAJtRTFv8$zmKJOH4ZZ | B13: IfcWindow | C13: 750mm x 2200mm | D13: Level 2 | E13: 0.75 | F13: 2.2 | G13: =E13*F13 -> 1.65 | H13: Yes | I13: Exterior - Brick on Block | J13: 2.5.1 | K13: 2.6.3
... A39: 2OBrcmyk58NupXoVOHUvPL | B39: IfcDoor | C39: 0864 x 2032mm | D39: Level 2 | E39: 0.864 | F39: 2.032 | G39: =E39*F39 -> 1.755648 | H39: No | I39: Interior - Partition (92mm Stud) | J39: 2.7.2 | K39: 2.8.2

Sheet Materials
A1: Material take-off from IFC material layer sets
A2: Layer area = element adopted area (one face per layer); layer volume = area x thickness. A different VIEW of the same elements - not additional to the BoQ.
A4: BoQ key | B4: Element type | C4: Category | D4: Layer # | E4: Material (as in IFC) | F4: Normalised material | G4: Thickness (mm) | H4: Element area (m2) | I4: Layer volume (m3) | K4: Material (as in IFC) | L4: Normalised name (edit)
A5: 1.03 | B5: Foundation - Concrete (417mm) | C5: Wall | D5: 1 | E5: Concrete - Cast In Situ | F5: =INDEX($L$5:$L$21,MATCH(E5,$K$5:$K$21,0)) -> Concrete - Cast In Situ | G5: 417 | H5: =SUMIFS(Register!$I:$I,Register!$F:$F,A5) -> 64.415 | I5: =H5*G5/1000 -> 26.861055 | K5: Ceramic Tile | L5: Ceramic Tile
A6: 1.04 | B6: Foundation - Concrete (435mm) | C6: Wall | D6: 1 | E6: Concrete - Cast In Situ | F6: =INDEX($L$5:$L$21,MATCH(E6,$K$5:$K$21,0)) -> Concrete - Cast In Situ | G6: 435 | H6: =SUMIFS(Register!$I:$I,Register!$F:$F,A6) -> 12.483345 | I6: =H6*G6/1000 -> 5.4302551 | K6: Concrete | L6: Concrete - Cast In Situ
A7: 1.06 | B7: 127mm Slab on Grade | C7: Floor | D7: 1 | E7: Concrete | F7: =INDEX($L$5:$L$21,MATCH(E7,$K$5:$K$21,0)) -> Concrete - Cast In Situ | G7: 127 | H7: =SUMIFS(Register!$I:$I,Register!$F:$F,A7) -> 129.68636 | I7: =H7*G7/1000 -> 16.470167 | K7: Concrete - Cast In Situ | L7: Concrete - Cast In Situ
A8: 2.2.1 | B8: Residential - Wood Joist with Subflooring | C8: Floor | D8: 1 | E8: Wood - Sheathing - plywood | F8: =INDEX($L$5:$L$21,MATCH(E8,$K$5:$K$21,0)) -> Wood - Sheathing - plywood | G8: 19 | H8: =SUMIFS(Register!$I:$I,Register!$F:$F,A8) -> 118.56277 | I8: =H8*G8/1000 -> 2.2526925 | K8: Insulation / Thermal Barriers - Rigid insulation | L8: Insulation / Thermal Barriers - Rigid insulation
A9: 2.2.1 | B9: Residential - Wood Joist with Subflooring | C9: Floor | D9: 2 | E9: Wood - Dimensional Lumber | F9: =INDEX($L$5:$L$21,MATCH(E9,$K$5:$K$21,0)) -> Wood - Dimensional Lumber | G9: 286 | H9: =SUMIFS(Register!$I:$I,Register!$F:$F,A9) -> 118.56277 | I9: =H9*G9/1000 -> 33.908951 | K9: Insulation / Thermal Barriers - Semi-rigid insulation | L9: Insulation / Thermal Barriers - Semi-rigid insulation
A10: 2.3.1 | B10: Live Roof over Wood Joist Flat Roof | C10: Roof | D10: 1 | E10: Site - Grass | F10: =INDEX($L$5:$L$21,MATCH(E10,$K$5:$K$21,0)) -> Site - Grass | G10: 64 | H10: =SUMIFS(Register!$I:$I,Register!$F:$F,A10) -> 132.92604 | I10: =H10*G10/1000 -> 8.5072663 | K10: Masonry - Brick | L10: Masonry - Brick
A11: 2.3.1 | B11: Live Roof over Wood Joist Flat Roof | C11: Roof | D11: 2 | E11: Roofing - Barrier | F11: =INDEX($L$5:$L$21,MATCH(E11,$K$5:$K$21,0)) -> Roofing - Barrier | G11: 6 | H11: =SUMIFS(Register!$I:$I,Register!$F:$F,A11) -> 132.92604 | I11: =H11*G11/1000 -> 0.79755622 | K11: Masonry - Concrete Block | L11: Masonry - Concrete Block
A12: 2.3.1 | B12: Live Roof over Wood Joist Flat Roof | C12: Roof | D12: 3 | E12: Roofing - EPDM Membrane | F12: =INDEX($L$5:$L$21,MATCH(E12,$K$5:$K$21,0)) -> Roofing - EPDM Membrane | G12: 6 | H12: =SUMIFS(Register!$I:$I,Register!$F:$F,A12) -> 132.92604 | I12: =H12*G12/1000 -> 0.79755622 | K12: Masonry - Grout | L12: Masonry - Grout
A13: 2.3.1 | B13: Live Roof over Wood Joist Flat Roof | C13: Roof | D13: 4 | E13: Insulation / Thermal Barriers - Rigid insulation | F13: =INDEX($L$5:$L$21,MATCH(E13,$K$5:$K$21,0)) -> Insulation / Thermal Barriers - Rigid insulation | G13: 76 | H13: =SUMIFS(Register!$I:$I,Register!$F:$F,A13) -> 132.92604 | I13: =H13*G13/1000 -> 10.102379 | K13: Metal - Stud Layer | L13: Metal - Stud Layer
A14: 2.3.1 | B14: Live Roof over Wood Joist Flat Roof | C14: Roof | D14: 5 | E14: Wood - Sheathing - plywood | F14: =INDEX($L$5:$L$21,MATCH(E14,$K$5:$K$21,0)) -> Wood - Sheathing - plywood | G14: 19 | H14: =SUMIFS(Register!$I:$I,Register!$F:$F,A14) -> 132.92604 | I14: =H14*G14/1000 -> 2.5255947 | K14: Misc. Air Layers - Air Space | L14: Misc. Air Layers - Air Space
A15: 2.3.1 | B15: Live Roof over Wood Joist Flat Roof | C15: Roof | D15: 6 | E15: Wood - Dimensional Lumber | F15: =INDEX($L$5:$L$21,MATCH(E15,$K$5:$K$21,0)) -> Wood - Dimensional Lumber | G15: 286 | H15: =SUMIFS(Register!$I:$I,Register!$F:$F,A15) -> 132.92604 | I15: =H15*G15/1000 -> 38.016846 | K15: Plasterboard | L15: Plasterboard
A16: 2.5.1 | B16: Exterior - Brick on Block | C16: Wall | D16: 1 | E16: Masonry - Brick | F16: =INDEX($L$5:$L$21,MATCH(E16,$K$5:$K$21,0)) -> Masonry - Brick | G16: 92 | H16: =SUMIFS(Register!$I:$I,Register!$F:$F,A16) -> 235.77923 | I16: =H16*G16/1000 -> 21.691689 | K16: Roofing - Barrier | L16: Roofing - Barrier
... A21: 2.5.1 | B21: Exterior - Brick on Block | C21: Wall | D21: 6 | E21: Plasterboard | F21: =INDEX($L$5:$L$21,MATCH(E21,$K$5:$K$21,0)) -> Plasterboard | G21: 16 | H21: =SUMIFS(Register!$I:$I,Register!$F:$F,A21) -> 235.77923 | I21: =H21*G21/1000 -> 3.7724676 | K21: Wood - Sheathing - plywood | L21: Wood - Sheathing - plywood
A22: 2.5.2 | B22: Exterior - Brick on Block | C22: Wall | D22: 1 | E22: Masonry - Brick | F22: =INDEX($L$5:$L$21,MATCH(E22,$K$5:$K$21,0)) -> Masonry - Brick | G22: 92 | H22: =SUMIFS(Register!$I:$I,Register!$F:$F,A22) -> 31.382988 | I22: =H22*G22/1000 -> 2.8872349
A23: 2.5.2 | B23: Exterior - Brick on Block | C23: Wall | D23: 2 | E23: Misc. Air Layers - Air Space | F23: =INDEX($L$5:$L$21,MATCH(E23,$K$5:$K$21,0)) -> Misc. Air Layers - Air Space | G23: 25 | H23: =SUMIFS(Register!$I:$I,Register!$F:$F,A23) -> 31.382988 | I23: =H23*G23/1000 -> 0.7845747
A24: 2.5.2 | B24: Exterior - Brick on Block | C24: Wall | D24: 3 | E24: Insulation / Thermal Barriers - Rigid insulation | F24: =INDEX($L$5:$L$21,MATCH(E24,$K$5:$K$21,0)) -> Insulation / Thermal Barriers - Rigid insulation | G24: 50 | H24: =SUMIFS(Register!$I:$I,Register!$F:$F,A24) -> 31.382988 | I24: =H24*G24/1000 -> 1.5691494
A25: 2.5.2 | B25: Exterior - Brick on Block | C25: Wall | D25: 4 | E25: Masonry - Concrete Block | F25: =INDEX($L$5:$L$21,MATCH(E25,$K$5:$K$21,0)) -> Masonry - Concrete Block | G25: 193 | H25: =SUMIFS(Register!$I:$I,Register!$F:$F,A25) -> 31.382988 | I25: =H25*G25/1000 -> 6.0569167
A26: 2.5.2 | B26: Exterior - Brick on Block | C26: Wall | D26: 5 | E26: Metal - Stud Layer | F26: =INDEX($L$5:$L$21,MATCH(E26,$K$5:$K$21,0)) -> Metal - Stud Layer | G26: 41 | H26: =SUMIFS(Register!$I:$I,Register!$F:$F,A26) -> 31.382988 | I26: =H26*G26/1000 -> 1.2867025
A27: 2.5.2 | B27: Exterior - Brick on Block | C27: Wall | D27: 6 | E27: Plasterboard | F27: =INDEX($L$5:$L$21,MATCH(E27,$K$5:$K$21,0)) -> Plasterboard | G27: 16 | H27: =SUMIFS(Register!$I:$I,Register!$F:$F,A27) -> 31.382988 | I27: =H27*G27/1000 -> 0.50212781
A28: 2.7.1 | B28: Party Wall - CMU Residential Unit Dimising Wall | C28: Wall | D28: 1 | E28: Plasterboard | F28: =INDEX($L$5:$L$21,MATCH(E28,$K$5:$K$21,0)) -> Plasterboard | G28: 16 | H28: =SUMIFS(Register!$I:$I,Register!$F:$F,A28) -> 71.669546 | I28: =H28*G28/1000 -> 1.1467127
A29: 2.7.1 | B29: Party Wall - CMU Residential Unit Dimising Wall | C29: Wall | D29: 2 | E29: Metal - Stud Layer | F29: =INDEX($L$5:$L$21,MATCH(E29,$K$5:$K$21,0)) -> Metal - Stud Layer | G29: 41 | H29: =SUMIFS(Register!$I:$I,Register!$F:$F,A29) -> 71.669546 | I29: =H29*G29/1000 -> 2.9384514
A30: 2.7.1 | B30: Party Wall - CMU Residential Unit Dimising Wall | C30: Wall | D30: 3 | E30: Masonry - Concrete Block | F30: =INDEX($L$5:$L$21,MATCH(E30,$K$5:$K$21,0)) -> Masonry - Concrete Block | G30: 193 | H30: =SUMIFS(Register!$I:$I,Register!$F:$F,A30) -> 71.669546 | I30: =H30*G30/1000 -> 13.832222
A31: 2.7.1 | B31: Party Wall - CMU Residential Unit Dimising Wall | C31: Wall | D31: 4 | E31: Misc. Air Layers - Air Space | F31: =INDEX($L$5:$L$21,MATCH(E31,$K$5:$K$21,0)) -> Misc. Air Layers - Air Space | G31: 50 | H31: =SUMIFS(Register!$I:$I,Register!$F:$F,A31) -> 71.669546 | I31: =H31*G31/1000 -> 3.5834773
A32: 2.7.1 | B32: Party Wall - CMU Residential Unit Dimising Wall | C32: Wall | D32: 5 | E32: Masonry - Concrete Block | F32: =INDEX($L$5:$L$21,MATCH(E32,$K$5:$K$21,0)) -> Masonry - Concrete Block | G32: 193 | H32: =SUMIFS(Register!$I:$I,Register!$F:$F,A32) -> 71.669546 | I32: =H32*G32/1000 -> 13.832222
A33: 2.7.1 | B33: Party Wall - CMU Residential Unit Dimising Wall | C33: Wall | D33: 6 | E33: Metal - Stud Layer | F33: =INDEX($L$5:$L$21,MATCH(E33,$K$5:$K$21,0)) -> Metal - Stud Layer | G33: 41 | H33: =SUMIFS(Register!$I:$I,Register!$F:$F,A33) -> 71.669546 | I33: =H33*G33/1000 -> 2.9384514
... A51: 8.1 | B51: 150mm Exterior Slab on Grade | C51: Floor | D51: 1 | E51: Concrete - Cast In Situ | F51: =INDEX($L$5:$L$21,MATCH(E51,$K$5:$K$21,0)) -> Concrete - Cast In Situ | G51: 150 | H51: =SUMIFS(Register!$I:$I,Register!$F:$F,A51) -> 50.839714 | I51: =H51*G51/1000 -> 7.6259572
A53: Summary by normalised material
B54: Normalised material | C54: Total layer area (m2) | D54: Total volume (m3)
B55: Ceramic Tile | C55: =SUMIFS($H$5:$H$51,$F$5:$F$51,B55) -> 44.909772 | D55: =SUMIFS($I$5:$I$51,$F$5:$F$51,B55) -> 0.44909772
B56: Concrete - Cast In Situ | C56: =SUMIFS($H$5:$H$51,$F$5:$F$51,B56) -> 257.42442 | D56: =SUMIFS($I$5:$I$51,$F$5:$F$51,B56) -> 56.387434
B57: Insulation / Thermal Barriers - Rigid insulation | C57: =SUMIFS($H$5:$H$51,$F$5:$F$51,B57) -> 400.08825 | D57: =SUMIFS($I$5:$I$51,$F$5:$F$51,B57) -> 23.46049
B58: Insulation / Thermal Barriers - Semi-rigid insulation | C58: =SUMIFS($H$5:$H$51,$F$5:$F$51,B58) -> 196.92062 | D58: =SUMIFS($I$5:$I$51,$F$5:$F$51,B58) -> 0.59076185
B59: Masonry - Brick | C59: =SUMIFS($H$5:$H$51,$F$5:$F$51,B59) -> 267.16222 | D59: =SUMIFS($I$5:$I$51,$F$5:$F$51,B59) -> 24.578924
B60: Masonry - Concrete Block | C60: =SUMIFS($H$5:$H$51,$F$5:$F$51,B60) -> 410.50131 | D60: =SUMIFS($I$5:$I$51,$F$5:$F$51,B60) -> 79.226752
B61: Masonry - Grout | C61: =SUMIFS($H$5:$H$51,$F$5:$F$51,B61) -> 44.909772 | D61: =SUMIFS($I$5:$I$51,$F$5:$F$51,B61) -> 0.13472932
B62: Metal - Stud Layer | C62: =SUMIFS($H$5:$H$51,$F$5:$F$51,B62) -> 830.85803 | D62: =SUMIFS($I$5:$I$51,$F$5:$F$51,B62) -> 47.062721
B63: Misc. Air Layers - Air Space | C63: =SUMIFS($H$5:$H$51,$F$5:$F$51,B63) -> 338.83176 | D63: =SUMIFS($I$5:$I$51,$F$5:$F$51,B63) -> 10.262533
...

Sheet Rooms
A1: Number | B1: Name | C1: Level | D1: Category | E1: Area (m2) | F1: Perimeter (m) | G1: Height (m) | H1: Volume (m3) | I1: GSA BIM area (m2) | J1: In NIA? (edit)
A2: A101 | B2: Foyer | C2: Level 1 | D2: General Residential Space | E2: 17.936237 | F2: 24.216 | G2: 2.6 | H2: 40.241254 | I2: 17.936237 | J2: Y
A3: A102 | B3: Living Room | C3: Level 1 | D3: Living Spaces | E3: 30.141645 | F3: 22.028 | G3: 2.6 | H3: 71.39069 | I3: 30.141645 | J3: Y
A4: A103 | B4: Kitchen | C4: Level 1 | D4: Kitchen | E4: 13.897501 | F4: 16.419461 | G4: 2.6 | H4: 33.512179 | I4: 13.897501 | J4: Y
A5: A104 | B5: Bathroom 1 | C5: Level 1 | D5: Bathroom | E5: 3.997752 | F5: 8.204 | G5: 2.6 | H5: 8.1774449 | I5: 3.997752 | J5: Y
A6: A105 | B6: Stair | C6: Level 1 | D6: Stairway | E6: 4.9221725 | F6: 10.4958 | G6: 5.7 | H6: 20.796062 | I6: 4.9221725 | J6: Y
A7: B101 | B7: Foyer | C7: Level 1 | D7: General Residential Space | E7: 17.936237 | F7: 24.216 | G7: 2.6 | H7: 40.241254 | I7: 17.936237 | J7: Y
A8: B102 | B8: Living Room | C8: Level 1 | D8: Living Spaces | E8: 30.141645 | F8: 22.028 | G8: 2.6 | H8: 71.39069 | I8: 30.141645 | J8: Y
A9: B103 | B9: Kitchen | C9: Level 1 | D9: Kitchen | E9: 13.897501 | F9: 16.419461 | G9: 2.6 | H9: 33.512179 | I9: 13.897501 | J9: Y
A10: B104 | B10: Bathroom 1 | C10: Level 1 | D10: Bathroom | E10: 3.997752 | F10: 8.204 | G10: 2.6 | H10: 8.1774449 | I10: 3.997752 | J10: Y
A11: B105 | B11: Room | C11: Level 1 | D11: Stairway | E11: 4.9221725 | F11: 10.4958 | G11: 5.7 | H11: 20.796062 | I11: 4.9221725 | J11: Y
A12: A201 | B12: Hallway | C12: Level 2 | D12: General Residential Space | E12: 7.7999547 | F12: 15.319 | G12: 2.9 | H12: 18.115464 | I12: 7.7999547 | J12: Y
A13: A202 | B13: Bedroom 1 | C13: Level 2 | D13: Bedroom | E13: 26.119314 | F13: 21.422 | G13: 2.6 | H13: 56.893582 | I13: 26.119314 | J13: Y
... A22: R301 | B22: Roof | C22: Roof | D22: Other General Facility Service Spaces | E22: 145.72169 | F22: 51.532 | G22: 3 | H22: 405.45347 | I22: 145.72169 | J22: N
B24: Net internal area by level
C25: Level 1 | E25: =SUMIFS($E$2:$E$22,$C$2:$C$22,C25,$J$2:$J$22,"Y") -> 141.79062
C26: Level 2 | E26: =SUMIFS($E$2:$E$22,$C$2:$C$22,C26,$J$2:$J$22,"Y") -> 134.53426
C27: Roof | E27: =SUMIFS($E$2:$E$22,$C$2:$C$22,C27,$J$2:$J$22,"Y") -> 0
C28: Total NIA | E28: =SUM(E25:E27) -> 276.32488
B29: R301 is the roof surface space (green roof), excluded by default. Stair spaces A105/B105 are double height and counted once on Level 1.

Sheet QA
A1: QA log - what the checks found and what was done about it
A3: Status | B3: Element(s) | C3: Finding | D3: Action / decision
A4: Info | B4: Whole model | C4: No IFC BaseQuantities present (Revit 2011 export). Only PSet_Revit_Dimensions and GSA space areas. | D4: Used Revit-reported values as primary source and recomputed every solid from geometry as an independent check.
A5: Resolved | B5: Party wall 2.7.1 (Level 2, IfcWall) | C5: Body exported as IfcFaceBasedSurfaceModel with inconsistent face winding: naive mesh volume 432.97 m3 vs reported 25.83 m3. | D5: Repaired normals before measuring; repaired volume 25.830 m3 matches reported exactly.
A6: Resolved | B6: Party wall 2.7.1 (Level 1, 2.2 m stub) | C6: Geometry 2.856 m3 vs reported 2.011 m3 (+42%). Solid-intersection test shows two 0.379 m3 overlaps with the adjacent party walls at T-junctions. | D6: Adopted reported (join-aware) volume. Geometry minus overlaps = 2.098 m3, within ~4% of reported.
A7: Resolved | B7: Walls 2.5.1 (Level 2) and 2.7.1 (Level 1) | C7: Revit "Area" does not equal Volume / layer-set thickness on 7 walls: the 4 Level 2 exterior walls differ by ~1.2 m2 each (matches two 819x759 windows not deducted from Area but deducted from Volume); the party walls differ by 1.2-8.6 m2. | D7: Wall areas adopted as Volume / thickness for every wall, so area, volume and material layers are internally consistent. Opening add-back threshold is a parameter.
A8: Minor | B8: Steel beams 2.1.x | C8: Geometric volume 3.5-4.7% above Revit volume. | D8: Steel measured by length x nominal mass per metre (W-section designation), with volume x density as a cross-check in the register.
A9: Check | B9: Ceilings 3.3.1 (187462 / 187470) | C9: Two ceiling elements overlap by 0.181 m3 (~3.2 m2 of ceiling modelled twice). | D9: Not auto-deducted. Flagged for the modeller; possible over-measure of ~3.2 m2.
A10: Info | B10: Beams vs exterior walls; partitions vs floor zone | C10: Remaining solid overlaps (beam bearings inside brick walls, partitions running through the joist floor, ceilings clipping walls) total ~0.9 m3. | D10: Treated as normal modelling tolerance; each element measured on its own. Listed in overlaps.json.
A11: Info | B11: IfcRoof / IfcStair | C11: Roof geometry lives on a child IfcSlab; stairs are aggregates of flights, stringers (IfcMember) and railings. | D11: Measured at the parent object; child parts kept in register with count 0 (except railings, which are measured as their own items).
A12: Assumption | B12: Strip footings 1.01 | C12: No material association on IfcFooting. | D12: Concrete assumed from type name "Bearing Footing - 900 x 300"; 300 mm depth used for formwork derivation.
A13: Data quality | B13: Party wall type | C13: Pset_WallCommon.IsExternal = TRUE on the party (unit-dividing) wall. | D13: Classified as internal wall (2.7) by type, overriding the flag.
A14: Data quality | B14: Skylights 2.3.2 | C14: Pset_WindowCommon.IsExternal = FALSE on roof lights. | D14: Classified under Roof by host element.
... A18: Data quality | B18: Material names | C18: Two names for the same material: "Concrete" (127 mm slab) and "Concrete - Cast In Situ". | D18: Merged via the editable naming dictionary on the Materials sheet (cols K:L).

Sheet Params
A1: Parameters (edit the yellow cells - everything downstream recalculates)
A3: Parameter | B3: Value | C3: Unit | D3: Used by / source
A4: Steel density | B4: 7850 | C4: kg/m3 | D4: Register col O - cross-check of beam mass from volume. Standard value for structural steel.
A5: Opening add-back threshold | B5: 0 | C5: m2 | D5: Wall areas: openings with W x H <= this value are added back (not deducted). 0 = deduct all openings (model net). Set per your measurement standard.
A6: Strip footing depth | B6: 0.3 | C6: m | D6: BoQ 1.02 formwork. From type name "Bearing Footing - 900 x 300".
A7: Ground slab thickness | B7: 0.127 | C7: m | D7: BoQ 1.08 edge formwork. From layer set "127mm Slab on Grade".
A8: Exterior slab thickness | B8: 0.15 | C8: m | D8: BoQ 8.3 edge formwork. From layer set "150mm Exterior Slab on Grade".
